Workbook

Sheet TOMA DE DATOS
B2: Juego 1(jenga nuevo) | F2: Juego 2 (jenga viejo) | J2: Juego 3 (jenga Viejo) | N2: Juego 4 (jenga nuevo) | R2: Juego 5 (jenga viejo) | V2: Juego 6 (jenga viejo) | Z2: Juego 7 (Jenga nuevo) | AD2: Juego 8 (Jenga VIEJO) | AH2: Juego 9 (Jenga VIEJO) | AL2: Juego 10 (Jenga VIEJO) | AP2: Juego 11 (Jenga VIEJO) | AT2: Juego 12 (Jenga VIEJO) | AX2: Juego 13 (Jenga VIEJO) | BB2: Juego 14 (Jenga VIEJO) | BF2: Juego 15 (Jenga VIEJO) | BJ2: Juego 16 (Jenga VIEJO) | BN2: Juego 17 (Jenga VIEJO) | BR2: Juego 18 (Jenga VIEJO) | BV2: Juego 19 (Jenga VIEJO) | BZ2: Juego 20 (Jenga NUEVO)
B3: # de jugadores | D3: 2 | F3: # de jugadores | H3: 2 | J3: # de jugadores | L3: 3 | N3: # de jugadores | P3: 4 | R3: # de jugadores | T3: 3 | V3: # de jugadores | X3: 3 | Z3: # de jugadores | AB3: 4 | AD3: # de jugadores | AF3: 3 | AH3: # de jugadores | AJ3: 4 | AL3: # de jugadores | AN3: 3 | AP3: # de jugadores | AR3: 3 | AT3: # de jugadores | AV3: 3 | AX3: # de jugadores | AZ3: 4 | BB3: # de jugadores | BD3: 4 | BF3: # de jugadores | BH3: 4 | BJ3: # de jugadores | BL3: 3 | BN3: # de jugadores | BP3: 4 | BR3: # de jugadores | BT3: 4 | BV3: # de jugadores | BX3: 2 | BZ3: # de jugadores | CB3: 2
B4: intento | C4: segundos | D4: mano | F4: intento | G4: segundos | H4: mano | J4: intento | K4: segundos | L4: mano | N4: intento | O4: segundos | P4: mano | R4: intento | S4: segundos | T4: mano | V4: intento | W4: segundos | X4: mano | Z4: intento | AA4: segundos | AB4: mano | AD4: intento | AE4: segundos | AF4: mano | AH4: intento | AI4: segundos | AJ4: mano | AL4: intento | AM4: segundos | AN4: mano | AP4: intento | AQ4: segundos | AR4: mano | AT4: intento | AU4: segundos | AV4: mano | AX4: intento | AY4: segundos | AZ4: mano | BB4: intento | BC4: segundos | BD4: mano | BF4: intento | BG4: segundos | BH4: mano | BJ4: intento | BK4: segundos | BL4: mano | BN4: intento | BO4: segundos | BP4: mano | BR4: intento | BS4: segundos | BT4: mano | BV4: intento | BW4: segundos | BX4: mano | BZ4: intento | CA4: segundos | CB4: mano
B5: 1 | C5: 4.79 | D5: dominante | F5: 1 | G5: 5.39 | H5: no dominante | J5: 1 | K5: 4/1/1900 9,50,24 | L5: dominante | N5: 1 | O5: 3.42 | P5: no dominante | R5: 1 | S5: 2.63 | T5: dominante | V5: 1 | W5: 8.39 | X5: no dominante | Z5: 1 | AA5: 4.99 | AB5: dominante | AD5: 1 | AE5: 12.54 | AF5: domimante | AH5: 1 | AI5: 4.69 | AJ5: no dominante | AL5: 1 | AM5: 4.03 | AN5: dominante | AP5: 1 | AQ5: 11.06 | AR5: dominante | AT5: 1 | AU5: 24.87 | AV5: dominante | AX5: 1 | AY5: 8/1/1900 8,09,36 | AZ5: dominante | BB5: 1 | BC5: 21.67 | BD5: no dominante | BF5: 1 | BG5: 5.25 | BH5: dominante | BJ5: 1 | BK5: 7.17 | BL5: no dominante | BN5: 1 | BO5: 5.64 | BP5: no dominante | BR5: 1 | BS5: 11.11 | BT5: no dominante | BV5: 1 | BW5: 3.22 | BX5: no dominante | BZ5: 1 | CA5: 6.12 | CB5: dominante
B6: 2 | C6: 6.26 | D6: dominante | F6: 2 | G6: 2.45 | H6: no dominante | J6: 2 | K6: 11.39 | L6: no dominante | N6: 2 | O6: 7.68 | P6: no dominante | R6: 2 | S6: 7.99 | T6: no dominante | V6: 2 | W6: 7 | X6: no dominante | Z6: 2 | AA6: 11.79 | AB6: dominante | AD6: 2 | AE6: 13.99 | AF6: domimante | AH6: 2 | AI6: 15.03 | AJ6: no dominante | AL6: 2 | AM6: 12.43 | AN6: dominante | AP6: 2 | AQ6: 6.86 | AR6: dominante | AT6: 2 | AU6: 1,23 | AV6: dominante | AX6: 2 | AY6: 3.66 | AZ6: dominante | BB6: 2 | BC6: 40.4 | BD6: no dominante | BF6: 2 | BG6: 4.7 | BH6: no dominante | BJ6: 2 | BK6: 3.03 | BL6: dominante | BN6: 2 | BO6: 3.58 | BP6: no dominante | BR6: 2 | BS6: 4.55 | BT6: dominante | BV6: 2 | BW6: 8.15 | BX6: no dominante | BZ6: 2 | CA6: 7.61 | CB6: dominante
B7: 3 | C7: 2.64 | D7: dominante | F7: 3 | G7: 6.99 | H7: no dominante | J7: 3 | K7: 8.28 | L7: dominante | N7: 3 | O7: 4.11 | P7: no dominante | R7: 3 | S7: 7.41 | T7: no dominante | V7: 3 | W7: 3.86 | X7: no dominante | Z7: 3 | AA7: 7.57 | AB7: no dominante | AD7: 3 | AE7: 19.41 | AF7: domimante | AH7: 3 | AI7: 6.5 | AJ7: no dominante | AL7: 3 | AM7: 24.74 | AN7: dominante | AP7: 3 | AQ7: 4.13 | AR7: dominante | AT7: 3 | AU7: 0,74 | AV7: dominante | AX7: 3 | AY7: 14.56 | AZ7: dominante | BB7: 3 | BC7: 7.8 | BD7: no dominante | BF7: 3 | BG7: 12.3 | BH7: dominante | BJ7: 3 | BK7: 24.29 | BL7: dominante | BN7: 3 | BO7: 11.84 | BP7: no dominante | BR7: 3 | BS7: 12.25 | BT7: dominante | BV7: 3 | BW7: 2.99 | BX7: no dominante | BZ7: 3 | CA7: 9.55 | CB7: dominante
B8: 4 | C8: 16.4 | D8: dominante | F8: 4 | G8: 2.75 | H8: no dominante | J8: 4 | K8: 3.61 | L8: dominante | N8: 4 | O8: 7.62 | P8: no dominante | R8: 4 | S8: 6.49 | T8: dominante | V8: 4 | W8: 5.97 | X8: no dominante | Z8: 4 | AA8: 17.35 | AB8: no dominante | AD8: 4 | AE8: 21.58 | AF8: domimante | AH8: 4 | AI8: 9.59 | AJ8: no dominante | AL8: 4 | AM8: 20.81 | AN8: dominante | AP8: 4 | AQ8: 6.93 | AR8: dominante | AT8: 4 | AU8: 20,86 | AV8: dominante | AX8: 4 | AY8: 12.47 | AZ8: dominante | BB8: 4 | BC8: 15.01 | BD8: no dominante | BF8: 4 | BG8: 26.73 | BH8: no dominante | BK8: =AVERAGE(BK5:BK7) -> 11.496667 | BN8: 4 | BO8: 13.83 | BP8: no dominante | BR8: 4 | BS8: 1.15 | BT8: no dominante | BV8: 4 | BW8: 7.22 | BX8: no dominante | BZ8: 4 | CA8: 34.49 | CB8: dominante
B9: 5 | C9: 7.38 | D9: dominante | F9: 5 | G9: 5.46 | H9: no dominante | J9: 5 | K9: 4.31 | L9: no dominante | N9: 5 | O9: 16.24 | P9: no dominante | R9: 5 | S9: 4.49 | T9: no dominante | V9: 5 | W9: 7.91 | X9: no dominante | Z9: 5 | AA9: 5.61 | AB9: dominante | AD9: 5 | AE9: 36.86 | AF9: domimante | AH9: 5 | AI9: 15.2 | AJ9: no dominante | AL9: 5 | AM9: 19.27 | AN9: dominante | AP9: 5 | AQ9: 5.08 | AR9: dominante | AT9: 5 | AU9: 5,17 | AV9: dominante | AX9: 5 | AY9: 6.11 | AZ9: dominante | BB9: 5 | BC9: 7.35 | BD9: no dominante | BF9: 5 | BG9: 10.32 | BH9: dominante | BK9: 11.5 | BN9: 5 | BO9: 12.49 | BP9: no dominante | BR9: 5 | BS9: 10.21 | BT9: no dominante | BV9: 5 | BW9: 13.22 | BX9: no dominante | BZ9: 5 | CA9: 7.83 | CB9: dominante
B10: 6 | C10: 9.69 | D10: dominante | F10: 6 | G10: 7.03 | H10: no dominante | J10: 6 | K10: 12.45 | L10: dominante | N10: 6 | O10: 6.29 | P10: no dominante | R10: 6 | S10: 4.81 | T10: no dominante | V10: 6 | W10: 10.1 | X10: no dominante | Z10: 6 | AA10: 19.63 | AB10: dominante | AD10: 6 | AE10: 38.85 | AF10: domimante | AH10: 6 | AI10: 9.18 | AJ10: no dominante | AL10: 6 | AM10: 5.06 | AN10: dominante | AP10: 6 | AQ10: 7.31 | AR10: dominante | AT10: 6 | AU10: 10,87 | AV10: dominante | AX10: 6 | AY10: 11.14 | AZ10: dominante | BB10: 6 | BC10: 14.11 | BD10: no dominante | BF10: 6 | BG10: 4.86 | BH10: no dominante | BN10: 6 | BO10: 20.56 | BP10: no dominante | BR10: 6 | BS10: 13.73 | BT10: dominante | BV10: 6 | BW10: 8.83 | BX10: no dominante | BZ10: 6 | CA10: 36.59 | CB10: dominante
B11: 7 | C11: 7.69 | D11: dominante | F11: 7 | G11: 5.18 | H11: no dominante | J11: 7 | K11: 5.56 | L11: dominante | N11: 7 | O11: 6.93 | P11: no dominante | R11: 7 | S11: 6.45 | T11: dominante | V11: 7 | W11: 4.01 | X11: no dominante | Z11: 7 | AA11: 7.54 | AB11: no dominante | AD11: 7 | AE11: 15.06 | AF11: domimante | AH11: 7 | AI11: 6.01 | AJ11: no dominante | AM11: =AVERAGE(AM5:AM10) -> 14.39 | AP11: 7 | AQ11: 6.06 | AR11: dominante | AT11: 7 | AU11: 26,09 | AV11: dominante | AX11: 7 | AY11: 18.08 | AZ11: dominante | BB11: 7 | BC11: 12.09 | BD11: no dominante | BF11: 7 | BG11: 13.11 | BH11: dominante | BN11: 7 | BO11: 8.58 | BP11: no dominante | BR11: 7 | BS11: 7.26 | BT11: dominante | BV11: 7 | BW11: 12.71 | BX11: no dominante | BZ11: 7 | CA11: 13.29 | CB11: dominante
B12: 8 | C12: 10.06 | D12: dominante | F12: 8 | G12: 4.93 | H12: no dominante | J12: 8 | K12: 6.82 | L12: no dominante | N12: 8 | O12: 5.71 | P12: no dominante | R12: 8 | S12: 11.75 | T12: no dominante | V12: 8 | W12: 24.9 | X12: no dominante | Z12: 8 | AA12: 13.66 | AB12: no dominante | AE12: =AVERAGE(AE5:AE11) -> 22.612857 | AH12: 8 | AI12: 7.63 | AJ12: no dominante | AP12: 8 | AQ12: 13.8 | AR12: dominante | AT12: 8 | AU12: 24,65 | AV12: dominante | AX12: 8 | AY12: 13.4 | AZ12: dominante | BB12: 8 | BC12: 8.58 | BD12: no dominante | BF12: 8 | BG12: 34.37 | BH12: no dominante | BN12: 8 | BO12: 11.52 | BP12: no dominante | BR12: 8 | BS12: 11.77 | BT12: no dominante | BV12: 8 | BW12: 15.52 | BX12: no dominante | BZ12: 8 | CA12: 57.45 | CB12: dominante
B13: 9 | C13: 11.83 | D13: dominante | F13: 9 | G13: 12.96 | H13: no dominante | J13: 9 | K13: 16.41 | L13: dominante | N13: 9 | O13: 11.86 | P13: no dominante | R13: 9 | S13: 7.6 | T13: no dominante | V13: 9 | W13: 11.77 | X13: no dominante | Z13: 9 | AA13: 7.58 | AB13: dominante | AH13: 9 | AI13: 8.76 | AJ13: no dominante | AP13: 9 | AQ13: 13.18 | AR13: dominante | AT13: 9 | AU13: 5,24 | AV13: dominante | AX13: 9 | AY13: 12.26 | AZ13: dominante | BB13: 9 | BC13: 4.75 | BD13: no dominante | BF13: 9 | BG13: 18.44 | BH13: dominante | BN13: 9 | BO13: 16.75 | BP13: no dominante | BR13: 9 | BS13: 9.48 | BT13: no dominante | BV13: 9 | BW13: 17.24 | BX13: no dominante | BZ13: 9 | CA13: 10.5 | CB13: dominante
B14: 10 | C14: 13.85 | D14: dominante | F14: 10 | G14: 5.31 | H14: no dominante | J14: 10 | K14: 16.56 | L14: dominante | N14: 10 | O14: 15.86 | P14: no dominante | R14: 10 | S14: 8.64 | T14: dominante | V14: 10 | W14: 11.35 | X14: no dominante | Z14: 10 | AA14: 7.29 | AB14: dominante | AH14: 10 | AI14: 14.08 | AJ14: no dominante | AP14: 10 | AQ14: 12.6 | AR14: dominante | AT14: 10 | AU14: 12,66 | AV14: dominante | AX14: 10 | AY14: 9.82 | AZ14: dominante | BC14: =AVERAGE(BC5:BC13) -> 14.64 | BF14: 10 | BG14: 10.34 | BH14: no dominante | BN14: 10 | BO14: 11.78 | BP14: no dominante | BR14: 10 | BS14: 28.79 | BT14: dominante | BV14: 10 | BW14: 5.06 | BX14: no dominante | BZ14: 10 | CA14: 22 | CB14: dominante
B15: TIEMPO TOTAL | F15: 11 | G15: 10.93 | H15: no dominante | J15: 11 | K15: 9.5 | L15: no dominante | N15: 11 | O15: 9.48 | P15: no dominante | R15: 11 | S15: 5.49 | T15: no dominante | V15: 11 | W15: 12.51 | X15: no dominante | Z15: 11 | AA15: 15.1 | AB15: no dominante | AH15: 11 | AI15: 7.96 | AJ15: no dominante | AP15: 11 | AQ15: 50.27 | AR15: dominante | AT15: 11 | AU15: 12,15 | AV15: dominante | AX15: 11 | AY15: 14.45 | AZ15: dominante | BF15: 11 | BG15: 11.82 | BH15: dominante | BN15: 11 | BO15: 11.44 | BP15: no dominante | BR15: 11 | BS15: 10.01 | BT15: dominante | BV15: 11 | BW15: 14.83 | BX15: no dominante | BZ15: 11 | CA15: 29.43 | CB15: dominante
B16: PROMEDIO | C16: =AVERAGE(C5:C14) -> 9.059 | F16: 12 | G16: 11.11 | H16: no dominante | J16: 12 | K16: 15.8 | L16: dominante | N16: 12 | O16: 13.56 | P16: no dominante | R16: 12 | S16: 7.41 | T16: no dominante | V16: 12 | W16: 6.52 | X16: no dominante | Z16: 12 | AA16: 23.26 | AB16: no dominante | AH16: 12 | AI16: 4.03 | AJ16: no dominante | AP16: 12 | AQ16: 8.71 | AR16: dominante | AT16: 12 | AU16: 6,35 | AV16: dominante | AX16: 12 | AY16: 18.59 | BF16: 12 | BG16: 14.64 | BH16: no dominante | BO16: =AVERAGE(BO5:BO15) -> 11.637273 | BR16: 12 | BS16: 27.43 | BT16: no dominante | BV16: 12 | BW16: 9 | BX16: no dominante | BZ16: 12 | CA16: 40.14 | CB16: dominante
F17: 13 | G17: 10.41 | H17: no dominante | J17: 13 | K17: 9.94 | L17: dominante | N17: 13 | O17: 12.98 | P17: no dominante | R17: 13 | S17: 5.19 | T17: dominante | V17: 13 | W17: 7.36 | X17: no dominante | Z17: 13 | AA17: 9.64 | AB17: dominante | AI17: =AVERAGE(AI5:AI16) -> 9.055 | AP17: 13 | AQ17: 11.11 | AR17: dominante | AT17: 13 | AU17: 14,48 | AV17: dominante | AY17: =AVERAGE(AY5:AY16) -> 12.230909 | BF17: 13 | BG17: 23.54 | BH17: dominante | BR17: 13 | BS17: 7.64 | BT17: no dominante | BV17: 13 | BW17: 20.27 | BX17: no dominante | BZ17: 13 | CA17: 8.62 | CB17: dominante
B18: Juego 21 (Jenga VIEJO) | F18: 14 | G18: 10.35 | H18: no dominante | J18: 14 | K18: 7.97 | L18: no dominante | N18: 14 | O18: 8.95 | P18: no dominante | R18: 14 | S18: 12.05 | T18: no dominante | V18: 14 | W18: 13.58 | X18: no dominante | Z18: 14 | AA18: 33.05 | AB18: dominante | AP18: 14 | AQ18: 12.59 | AR18: dominante | AT18: 14 | AU18: 80,37 | AV18: dominante | BG18: =AVERAGE(BG5:BG17) -> 14.647692 | BR18: 14 | BS18: 13.32 | BT18: dominante | BV18: 14 | BW18: 12.5 | BX18: no dominante | BZ18: 14 | CA18: 19.26 | CB18: dominante
B19: # de jugadores | D19: 2 | F19: 15 | G19: 5.83 | H19: no dominante | J19: 15 | K19: 25.26 | L19: dominante | N19: 15 | O19: 45.2 | P19: no dominante | R19: 15 | S19: 5.22 | T19: no dominante | V19: 15 | W19: 21.73 | X19: no dominante | Z19: 15 | AA19: 26.23 | AB19: no dominante | AP19: 15 | AQ19: 7.59 | AR19: dominante | AT19: 15 | AU19: 32,10 | AV19: dominante | BG19: 14.65 | BR19: 15 | BS19: 15.51 | BT19: dominante | BV19: 15 | BW19: 11.13 | BX19: no dominante | CA19: =AVERAGE(CA6:CA18) -> 22.827692
B20: intento | C20: segundos | D20: mano | F20: 16 | G20: 8.98 | H20: no dominante | J20: 16 | K20: 7.07 | L20: dominante | O20: =AVERAGE(O5:O19) -> 11.726 | R20: 16 | S20: 9.1 | T20: dominante | V20: 16 | W20: 5.2 | X20: no dominante | Z20: 16 | AA20: 10.63 | AB20: no dominante | AP20: 16 | AQ20: 8.23 | AR20: dominante | AT20: 16 | AU20: 51,72 | AV20: dominante | BR20: 16 | BS20: 9.48 | BT20: no dominante | BV20: 16 | BW20: 21.88 | BX20: no dominante
B21: 1 | C21: 9.95 | D21: dominante | G21: =AVERAGE(G5:G20) -> 7.25375 | K21: =AVERAGE(K5:K20) -> 10.728667 | R21: 17 | S21: 10.61 | T21: no dominante | V21: 17 | W21: 12.98 | X21: no dominante | Z21: 17 | AA21: 9.26 | AB21: dominante | AP21: 17 | AQ21: 8.94 | AR21: dominante | AT21: 17 | AU21: 70,66 | AV21: dominante | BR21: 17 | BS21: 4.65 | BT21: no dominante | BV21: 17 | BW21: 32.36 | BX21: no dominante
B22: 2 | C22: 7.22 | D22: dominante | R22: 18 | S22: 6.04 | T22: no dominante | V22: 18 | W22: 18.74 | X22: no dominante | Z22: 18 | AA22: 8.82 | AB22: dominante | AP22: 18 | AQ22: 10.86 | AR22: dominante | AT22: 18 | AU22: 8,02 | AV22: dominante | BR22: 18 | BS22: 19.26 | BT22: dominante | BV22: 18 | BW22: 15.88 | BX22: no dominante
B23: 3 | C23: 9.05 | D23: dominante | N23: Juego 24 (Jenga viejo) | R23: 19 | S23: 14.6 | T23: dominante | V23: 19 | W23: 7.03 | X23: no dominante | Z23: 19 | AA23: 6.02 | AB23: no dominante | AP23: 19 | AQ23: 23.32 | AR23: dominante | AT23: 19 | AU23: 35,69 | AV23: dominante | BR23: 19 | BS23: 15.28 | BT23: dominante | BV23: 19 | BW23: 17.97 | BX23: no dominante
B24: 4 | C24: 6.97 | D24: dominante | F24: Juego 22 (Jenga nuevo) | J24: Juego 23 (Jenga nuevo) | N24: # de jugadores | P24: 2 | R24: 20 | S24: 5.41 | T24: no dominante | V24: 20 | W24: 61.2 | X24: no dominante | AA24: =AVERAGE(AA5:AA23) -> 12.895789 | AP24: 20 | AQ24: 6.76 | AR24: dominante | AT24: 20 | AU24: 29.49 | AV24: dominante | BR24: 20 | BS24: 14.18 | BT24: no dominante | BV24: 20 | BW24: 14.77 | BX24: no dominante
B25: 5 | C25: 7.24 | D25: dominante | F25: # de jugadores | H25: 2 | J25: # de jugadores | L25: 2 | N25: intento | O25: segundos | P25: mano | R25: 21 | S25: 7.72 | T25: no dominante | V25: 21 | W25: 6.96 | X25: no dominante | AP25: 21 | AQ25: 17.75 | AR25: dominante | AU25: =AVERAGE(AU5:AU24) -> 27.18 | BR25: 21 | BS25: 10.59 | BT25: no dominante | BV25: 21 | BW25: 6.95 | BX25: no dominante
B26: 6 | C26: 7.36 | D26: dominante | F26: intento | G26: segundos | H26: mano | J26: intento | K26: segundos | L26: mano | N26: 1 | O26: 8.5 | P26: no dominante | R26: 22 | S26: 5.9 | T26: dominante | V26: 22 | W26: 13.7 | X26: no dominante | AP26: 22 | AQ26: 35.54 | AR26: dominante | BR26: 22 | BS26: 9.6 | BT26: dominante | BW26: =AVERAGE(BW5:BW25) -> 12.938095
B27: 7 | C27: 7.61 | D27: dominante | F27: 1 | G27: 19.27 | H27: no dominante | J27: 1 | K27: 6.12 | L27: no dominante | N27: 2 | O27: 8.5 | P27: dominante | R27: 23 | S27: 19.56 | T27: no dominante | V27: 23 | W27: 15.68 | X27: no dominante | Z27: Juego 27 (Jenga viejo) | AD27: Juego 28 (Jenga VIEJO) | AH27: Juego 29 (Jenga VIEJO) | AL27: Juego 30 (Jenga VIEJO) | AP27: 23 | AQ27: 7.36 | AR27: dominante | AT27: Juego 32 (Jenga NUEVO) | AX27: Juego 33 (Jenga NUEVO) | BB27: Juego 34 (Jenga NUEVO) | BF27: Juego 35 (Jenga NUEVO) | BJ27: Juego 36 (Jenga NUEVO) | BN27: Juego 37 (Jenga VIEJO ) | BS27: =AVERAGE(BS5:BS26) -> 12.147727
B28: 8 | C28: 5.26 | D28: dominante | F28: 2 | G28: 15.53 | H28: no dominante | J28: 2 | K28: 8.39 | L28: dominante | N28: 3 | O28: 10 | P28: no dominante | R28: 24 | S28: 14.76 | T28: no dominante | V28: 24 | W28: 4.98 | X28: no dominante | Z28: # de jugadores | AB28: 3 | AD28: # de jugadores | AF28: 3 | AH28: # de jugadores | AJ28: 4 | AL28: # de jugadores | AN28: 4 | AP28: 24 | AQ28: 9.69 | AR28: dominante | AT28: # de jugadores | AV28: 2 | AX28: # de jugadores | AZ28: 3 | BB28: # de jugadores | BD28: 3 | BF28: # de jugadores | BH28: 3 | BJ28: # de jugadores | BL28: 3 | BN28: # de jugadores | BP28: 1 | BR28: Juego 38 (Jenga VIEJO ) | BV28: Juego 39 (Jenga VIEJO) | BZ28: Juego 40 (Jenga VIEJO)
B29: 9 | C29: 6.93 | D29: dominante | F29: 3 | G29: 9.06 | H29: no dominante | J29: 3 | K29: 6.84 | L29: no dominante | N29: 4 | O29: 5.3 | P29: dominante | R29: 25 | S29: 12.22 | T29: dominante | V29: 25 | W29: 10.26 | X29: no dominante | Z29: intento | AA29: segundos | AB29: mano | AD29: intento | AE29: segundos | AF29: mano | AH29: intento | AI29: segundos | AJ29: mano | AL29: intento | AM29: segundos | AN29: mano | AP29: 25 | AQ29: 63.78 | AR29: dominante | AT29: intento | AU29: segundos | AV29: mano | AX29: intento | AY29: segundos | AZ29: mano | BB29: intento | BC29: segundos | BD29: mano | BF29: intento | BG29: segundos | BH29: mano | BJ29: intento | BK29: segundos | BL29: mano | BN29: intento | BO29: segundos | BP29: mano | BR29: # de jugadores | BT29: 1 | BV29: # de jugadores | BX29: 1 | BZ29: # de jugadores | CB29: 1
B30: 10 | C30: 8.91 | D30: dominante | F30: 4 | G30: 11.77 | H30: no dominante | J30: 4 | K30: 21.51 | L30: dominante | N30: 5 | O30: 7.1 | P30: no dominante | R30: 26 | S30: 18.45 | T30: no dominante | V30: 26 | W30: 7.5 | X30: no dominante | Z30: 1 | AA30: 9 | AB30: dominante | AD30: 1 | AE30: 4.5 | AF30: no dominante | AH30: 1 | AI30: 5.2 | AJ30: dominante | AL30: 1 | AM30: 5.6 | AN30: dominante | AP30: 26 | AQ30: 52.19 | AR30: dominante | AT30: 1 | AU30: 6.6 | AV30: no dominante | AX30: 1 | AY30: 4.9 | AZ30: no dominante | BB30: 1 | BC30: 8.3 | BD30: no dominante | BF30: 1 | BG30: 5.9 | BH30: dominante | BJ30: 1 | BK30: 3.8 | BL30: no dominante | BN30: 1 | BO30: 7.07 | BP30: no dominante | BR30: intento | BS30: segundos | BT30: mano | BV30: intento | BW30: segundos | BX30: mano | BZ30: intento | CA30: segundos | CB30: mano
B31: 11 | C31: 4.89 | D31: dominante | F31: 5 | G31: 5.66 | H31: no dominante | J31: 5 | K31: 9.38 | L31: no dominante | N31: 6 | O31: 6.8 | P31: dominante | R31: 27 | S31: 11.75 | T31: no dominante | V31: 27 | W31: 15.16 | X31: no dominante | Z31: 2 | AA31: 7.7 | AB31: dominante | AD31: 2 | AE31: 6.9 | AF31: no dominante | AH31: 2 | AI31: 10 | AJ31: dominante | AL31: 2 | AM31: 5.5 | AN31: dominante | AP31: 27 | AQ31: 23.36 | AR31: dominante | AT31: 2 | AU31: 9.5 | AV31: no dominante | AX31: 2 | AY31: 29.7 | AZ31: no dominante | BB31: 2 | BC31: 10.2 | BD31: dominante | BF31: 2 | BG31: 9.2 | BH31: no dominante | BJ31: 2 | BK31: 21.4 | BL31: no dominante | BN31: 2 | BO31: 6.3 | BP31: no dominante | BR31: 1 | BS31: 5.79 | BT31: dominante | BV31: 1 | BW31: 9.18 | BX31: dominante | BZ31: 1 | CA31: 6.2 | CB31: no dominante
B32: 12 | C32: 3.52 | D32: dominante | F32: 6 | G32: 11.1 | H32: no dominante | J32: 6 | K32: 4.37 | L32: dominante | N32: 7 | O32: 9.3 | P32: no dominante | R32: 28 | S32: 24.17 | T32: dominante | V32: 28 | W32: 9.42 | X32: no dominante | Z32: 3 | AA32: 8.3 | AB32: dominante | AD32: 3 | AE32: 9.7 | AF32: no dominante | AH32: 3 | AI32: 15.9 | AJ32: no dominante | AL32: 3 | AM32: 12.9 | AN32: dominante | AP32: 28 | AQ32: 21.68 | AR32: dominante | AT32: 3 | AU32: 9 | AV32: no dominante | AX32: 3 | AY32: 6.8 | AZ32: no dominante | BB32: 3 | BC32: 7 | BD32: no dominante | BF32: 3 | BG32: 14.6 | BH32: dominante | BJ32: 3 | BK32: 4.3 | BL32: no dominante | BN32: 3 | BO32: 8.83 | BP32: no dominante | BR32: 2 | BS32: 8.83 | BT32: dominante | BV32: 2 | BW32: 44.39 | BX32: dominante | BZ32: 2 | CA32: 13.37 | CB32: no dominante
B33: 13 | C33: 6.28 | D33: dominante | F33: 7 | G33: 33.99 | H33: no dominante | J33: 7 | K33: 1.42 | L33: no dominante | N33: 8 | O33: 4.4 | P33: dominante | R33: 29 | S33: 21.98 | T33: no dominante | V33: 29 | W33: 11.96 | X33: no dominante | Z33: 4 | AA33: 5.5 | AB33: dominante | AD33: 4 | AE33: 4.4 | AF33: no dominante | AH33: 4 | AI33: 7.2 | AJ33: no dominante | AL33: 4 | AM33: 24.3 | AN33: dominante | AP33: 29 | AQ33: 36.44 | AR33: dominante | AT33: 4 | AU33: 8.8 | AV33: no dominante | AX33: 4 | AY33: 7.3 | AZ33: no dominante | BC33: =AVERAGE(BC30:BC32) -> 8.5 | BF33: 4 | BG33: 7 | BH33: dominante | BJ33: 4 | BK33: 4 | BL33: no dominante | BN33: 4 | BO33: 6.22 | BP33: no dominante | BR33: 3 | BS33: 7.86 | BT33: dominante | BV33: 3 | BW33: 5.75 | BX33: dominante | BZ33: 3 | CA33: 10.91 | CB33: no dominante
B34: 14 | C34: 11.88 | D34: dominante | F34: 8 | G34: 10.73 | H34: no dominante | J34: 8 | K34: 7.11 | L34: dominante | N34: 9 | O34: 5.3 | P34: no dominante | R34: 30 | S34: 11.14 | T34: no dominante | V34: 30 | W34: 11.53 | X34: no dominante | Z34: 5 | AA34: 5.8 | AB34: dominante | AD34: 5 | AE34: 5.5 | AF34: no dominante | AH34: 5 | AI34: 5.8 | AJ34: dominante | AL34: 5 | AM34: 5.8 | AN34: dominante | AP34: 30 | AQ34: 24.61 | AR34: dominante | AT34: 5 | AU34: 10.4 | AV34: no dominante | AX34: 5 | AY34: 10.1 | AZ34: no dominante | BF34: 5 | BG34: 14.4 | BH34: no dominante | BJ34: 5 | BK34: 8.2 | BL34: no dominante | BN34: 5 | BO34: 27.05 | BP34: no dominante | BR34: 4 | BS34: 5.9 | BT34: dominante | BV34: 4 | BW34: 4.69 | BX34: dominante | BZ34: 4 | CA34: 12.54 | CB34: no dominante
B35: 15 | C35: 8.47 | D35: dominante | F35: 9 | G35: 15.47 | H35: no dominante | J35: 9 | K35: 20.91 | L35: no dominante | N35: 10 | O35: 6.6 | P35: dominante | S35: =AVERAGE(S5:S34) -> 9.901 | W35: =AVERAGE(W5:W34) -> 12.308667 | Z35: 6 | AA35: 5.5 | AB35: dominante | AD35: 6 | AE35: 9.4 | AF35: no dominante | AH35: 6 | AI35: 8.5 | AJ35: dominante | AL35: 6 | AM35: 5 | AN35: dominante | AP35: 31 | AQ35: 7.78 | AR35: dominante | AT35: 6 | AU35: 5.1 | AV35: no dominante | AX35: 6 | AY35: 9.4 | AZ35: no dominante | BF35: 6 | BG35: 10.6 | BH35: dominante | BJ35: 6 | BK35: 7.9 | BL35: no dominante | BN35: 6 | BO35: 15.67 | BP35: no dominante | BR35: 5 | BS35: 13.28 | BT35: dominante | BV35: 5 | BW35: 17.81 | BX35: dominante | BZ35: 5 | CA35: 16.12 | CB35: no dominante
B36: 16 | C36: 12.83 | D36: dominante | F36: 10 | G36: 18.32 | H36: no dominante | J36: 10 | K36: 3.49 | L36: dominante | N36: 11 | O36: 14.2 | P36: no dominante | Z36: 7 | AA36: 5.3 | AB36: dominante | AD36: 7 | AE36: 7.1 | AF36: no dominante | AH36: 7 | AI36: 8 | AJ36: no dominante | AL36: 7 | AM36: 19.1 | AN36: dominante | AP36: 32 | AQ36: 68 | AR36: dominante | AT36: 7 | AU36: 12.3 | AV36: no dominante | AX36: 7 | AY36: 5.3 | AZ36: no dominante | BF36: 7 | BG36: 12.1 | BH36: dominante | BJ36: 7 | BK36: 14.9 | BL36: no dominante | BN36: 7 | BO36: 4.97 | BP36: no dominante | BR36: 6 | BS36: 3.57 | BT36: dominante | BV36: 6 | BW36: 14.15 | BX36: dominante | BZ36: 6 | CA36: 28.25 | CB36: no dominante
F37: 11 | G37: 20.01 | H37: no dominante | J37: 11 | K37: 30.06 | L37: no dominante | N37: 12 | O37: 8.9 | P37: dominante | Z37: 8 | AA37: 6.9 | AB37: dominante | AD37: 8 | AE37: 4.9 | AF37: no dominante | AH37: 8 | AI37: 8.4 | AJ37: no dominante | AL37: 8 | AM37: 13.9 | AN37: dominante | AP37: 33 | AQ37: 31.11 | AR37: dominante | AT37: 8 | AU37: 7 | AV37: no dominante | AX37: 8 | AY37: 15 | AZ37: no dominante | BF37: 8 | BG37: 16.4 | BH37: no dominante | BJ37: 8 | BK37: 17.2 | BL37: no dominante | BN37: 8 | BO37: 5.11 | BP37: no dominante | BR37: 7 | BS37: 11.19 | BT37: dominante | BV37: 7 | BW37: 4.21 | BX37: dominante | BZ37: 7 | CA37: 14.07 | CB37: no dominante
F38: 12 | G38: 8.62 | H38: no dominante | J38: 12 | K38: 20.31 | L38: dominante | N38: 13 | O38: 14 | P38: no dominante | R38: Juego 25 (Jenga nuevo) | V38: Juego 26 (Jenga nuevo) | Z38: 9 | AA38: 2.7 | AB38: dominante | AD38: 9 | AE38: 7.9 | AF38: no dominante | AH38: 9 | AI38: 11.1 | AJ38: dominante | AL38: 9 | AM38: 5.5 | AN38: dominante | AP38: 34 | AQ38: 5.43 | AR38: dominante | AT38: 9 | AU38: 9.9 | AV38: no dominante | AX38: 9 | AY38: 13.3 | AZ38: no dominante | BF38: 9 | BG38: 5.5 | BH38: dominante | BJ38: 9 | BK38: 16.9 | BL38: no dominante | BN38: 9 | BO38: 6.38 | BP38: no dominante | BR38: 8 | BS38: 5.36 | BT38: dominante | BV38: 8 | BW38: 5.87 | BX38: dominante | BZ38: 8 | CA38: 5.55 | CB38: no dominante
F39: 13 | G39: 13.53 | H39: no dominante | J39: 13 | K39: 22.39 | L39: no dominante | N39: 14 | O39: 14.5 | P39: dominante | R39: # de jugadores | T39: 4 | V39: # de jugadores | X39: 4 | Z39: 10 | AA39: 6.4 | AB39: dominante | AD39: 10 | AE39: 9 | AF39: no dominante | AH39: 10 | AI39: 13.7 | AJ39: dominante | AL39: 10 | AM39: 3 | AN39: dominante | AP39: 35 | AQ39: 27.83 | AR39: dominante | AT39: 10 | AU39: 6.7 | AV39: no dominante | AX39: 10 | AY39: 22.1 | AZ39: no dominante | BF39: 10 | BG39: 8.7 | BH39: dominante | BJ39: 10 | BK39: 10.3 | BL39: no dominante | BN39: 10 | BO39: 15.67 | BP39: no dominante | BR39: 9 | BS39: 8.26 | BT39: dominante | BV39: 9 | BW39: 6.69 | BX39: dominante | BZ39: 9 | CA39: 4.83 | CB39: no dominante
F40: 14 | G40: 14.9 | H40: no dominante | J40: 14 | K40: 10.16 | L40: dominante | N40: 15 | O40: 10.1 | P40: no dominante | R40: intento | S40: segundos | T40: mano | V40: intento | W40: segundos | X40: mano | Z40: 11 | AA40: 10.4 | AB40: dominante | AD40: 11 | AE40: 7.1 | AF40: no dominante | AH40: 11 | AI40: 29.1 | AJ40: no dominante | AL40: 11 | AM40: 11.9 | AN40: dominante | AQ40: =AVERAGE(AQ5:AQ39) -> 19.084 | AT40: 11 | AU40: 13.3 | AV40: no dominante | AX40: 11 | AY40: 9.7 | AZ40: no dominante | BF40: 11 | BG40: 4.5 | BH40: no dominante | BJ40: 11 | BK40: 32.5 | BL40: no dominante | BN40: 11 | BO40: 6.34 | BP40: no dominante | BR40: 10 | BS40: 8.99 | BT40: dominante | BV40: 10 | BW40: 8.65 | BX40: dominante | BZ40: 10 | CA40: 6.06 | CB40: no dominante
F41: 15 | G41: 6.19 | H41: no dominante | J41: 15 | K41: 19.71 | L41: no dominante | N41: 16 | O41: 6.8 | P41: dominante | R41: 1 | S41: 7.86 | T41: no dominante | V41: 1 | W41: 7.55 | X41: dominante | Z41: 12 | AA41: 21.1 | AB41: dominante | AD41: 12 | AE41: 9.4 | AF41: no dominante | AH41: 12 | AI41: 11.5 | AJ41: no dominante | AL41: 12 | AM41: 21.1 | AN41: dominante | AP41: Juego 31 (Jenga VIEJO) | AT41: 12 | AU41: 9 | AV41: no dominante | AX41: 12 | AY41: 18.6 | AZ41: no dominante | BF41: 12 | BG41: 8.2 | BH41: dominante | BJ41: 12 | BK41: 8 | BL41: no dominante | BN41: 12 | BO41: 10.76 | BP41: no dominante | BR41: 11 | BS41: 4.24 | BT41: dominante | BV41: 11 | BW41: 10.01 | BX41: dominante | BZ41: 11 | CA41: 5.1 | CB41: no dominante
...

Sheet FORMATO 1
A1: Juego | B1: Condicion de la torre | C1: Numero de jugadores | D1: Intento | E1: Segundos | F1: Mano Utilizada
A2: 1 | B2: si | C2: 2 | D2: 1 | E2: 4.79 | F2: dominante
A3: 1 | B3: si | C3: 2 | D3: 2 | E3: 6.26 | F3: dominante
A4: 1 | B4: si | C4: 2 | D4: 3 | E4: 2.64 | F4: dominante
A5: 1 | B5: si | C5: 2 | D5: 4 | E5: 16.4 | F5: dominante
A6: 1 | B6: si | C6: 2 | D6: 5 | E6: 7.38 | F6: dominante
A7: 1 | B7: si | C7: 2 | D7: 6 | E7: 9.69 | F7: dominante
A8: 1 | B8: si | C8: 2 | D8: 7 | E8: 7.69 | F8: dominante
A9: 1 | B9: si | C9: 2 | D9: 8 | E9: 10.06 | F9: dominante
A10: 1 | B10: si | C10: 2 | D10: 9 | E10: 11.83 | F10: dominante
A11: 1 | B11: si | C11: 2 | D11: 10 | E11: 13.85 | F11: dominante
A12: 2 | B12: no | C12: 2 | D12: 1 | E12: 5.39 | F12: no dominante
A13: 2 | B13: no | C13: 2 | D13: 2 | E13: 2.45 | F13: no dominante
... A374: 24 | B374: no | C374: 2 | D374: 2 | E374: 8.5 | F374: dominante
A375: 24 | B375: no | C375: 2 | D375: 3 | E375: 10 | F375: no dominante
A376: 24 | B376: no | C376: 2 | D376: 4 | E376: 5.3 | F376: dominante
A377: 24 | B377: no | C377: 2 | D377: 5 | E377: 7.1 | F377: no dominante
A378: 24 | B378: no | C378: 2 | D378: 6 | E378: 6.8 | F378: dominante
A379: 24 | B379: no | C379: 2 | D379: 7 | E379: 9.3 | F379: no dominante
A380: 24 | B380: no | C380: 2 | D380: 8 | E380: 4.4 | F380: dominante
A381: 24 | B381: no | C381: 2 | D381: 9 | E381: 5.3 | F381: no dominante
A382: 24 | B382: no | C382: 2 | D382: 10 | E382: 6.6 | F382: dominante
A383: 24 | B383: no | C383: 2 | D383: 11 | E383: 14.2 | F383: no dominante
A384: 24 | B384: no | C384: 2 | D384: 12 | E384: 8.9 | F384: dominante
A385: 24 | B385: no | C385: 2 | D385: 13 | E385: 14 | F385: no dominante
A386: 24 | B386: no | C386: 2 | D386: 14 | E386: 14.5 | F386: dominante
A387: 24 | B387: no | C387: 2 | D387: 15 | E387: 10.1 | F387: no dominante
A388: 24 | B388: no | C388: 2 | D388: 16 | E388: 6.8 | F388: dominante
A389: 24 | B389: no | C389: 2 | D389: 17 | E389: 6.1 | F389: no dominante
A390: 24 | B390: no | C390: 2 | D390: 18 | E390: 29.0 | F390: dominante
A391: 24 | B391: no | C391: 2 | D391: 19 | E391: 12.6 | F391: no dominante
A392: 24 | B392: no | C392: 2 | D392: 20 | E392: 13.5 | F392: dominante
A393: 24 | B393: no | C393: 2 | D393: 21 | E393: 11.0 | F393: no dominante
A394: 24 | B394: no | C394: 2 | D394: 22 | E394: 12.7 | F394: dominante
A395: 24 | B395: no | C395: 2 | D395: 23 | E395: 9.7 | F395: no dominante
A396: 24 | B396: no | C396: 2 | D396: 24 | E396: 7.0 | F396: dominante
A397: 24 | B397: no | C397: 2 | D397: 25 | E397: 29.8 | F397: no dominante
... A6423: 300 | B6423: si | C6423: 4 | D6423: 14 | E6423: 2.74 | F6423: no dominante

Sheet FORMATO 2
A1: Juego | B1: Condicion de la torre | C1: Numero de jugadores | D1: Piezas sacadas | E1: Promedio de segundos | F1: Mano Utilizada en la ultima pieza
A2: 1 | B2: Nuevo | C2: 2 | D2: 10 | E2: 9.06 | F2: dominante
A3: 2 | B3: Viejo | C3: 2 | D3: 16 | E3: 7.25 | F3: no dominante
A4: 3 | B4: Viejo | C4: 3 | D4: 16 | E4: 8 | F4: dominante
A5: 4 | B5: Nuevo | C5: 4 | D5: 15 | E5: 11.73 | F5: no dominante
A6: 5 | B6: Viejo | C6: 3 | D6: 30 | E6: 9.9 | F6: no dominante
A7: 6 | B7: Viejo | C7: 3 | D7: 30 | E7: 12.31 | F7: no dominante
A8: 7 | B8: Nuevo | C8: 4 | D8: 19 | E8: 12.9 | F8: no dominante
A9: 8 | B9: Viejo | C9: 3 | D9: 7 | E9: 22.61 | F9: dominante
A10: 9 | B10: Viejo | C10: 4 | D10: 12 | E10: 9.05 | F10: no dominante
A11: 10 | B11: Viejo | C11: 3 | D11: 6 | E11: 14.39 | F11: dominante
A12: 11 | B12: Viejo | C12: 3 | D12: 35 | E12: 19.08 | F12: dominante
A13: 12 | B13: Viejo | C13: 3 | D13: 20 | E13: 27.18 | F13: dominante
... A23: 22 | B23: Nuevo | C23: 2 | D23: 19 | E23: 16.78 | F23: no dominante
A24: 23 | B24: Nuevo | C24: 2 | D24: 16 | E24: =AVERAGE('TOMA DE DATOS'!$K$27:$K$42) -> 13.06875 | F24: dominante
A25: 24 | B25: Viejo | C25: 2 | D25: 39 | E25: =AVERAGE('TOMA DE DATOS'!$O$26:$O$64) -> 14.479487 | F25: no dominante
A26: 25 | B26: Nuevo | C26: 4 | D26: 4 | E26: =AVERAGE('TOMA DE DATOS'!$S$41:$S$44) -> 8.775 | F26: dominante
A27: 26 | B27: Nuevo | C27: 4 | D27: 12 | E27: =AVERAGE('TOMA DE DATOS'!$W$41:$W$52) -> 10.3225 | F27: no dominante
A28: 27 | B28: Viejo | C28: 3 | D28: 37 | E28: =AVERAGE('TOMA DE DATOS'!$AA$30:$AA$66) -> 11.597297 | F28: dominante
A29: 28 | B29: Viejo | C29: 3 | D29: 29 | E29: =AVERAGE('TOMA DE DATOS'!$AE$30:$AE$58) -> 10.8 | F29: no dominante
A30: 29 | B30: Viejo | C30: 4 | D30: 20 | E30: =AVERAGE('TOMA DE DATOS'!$AI$30:$AI$49) -> 11.918 | F30: no dominante
A31: 30 | B31: Viejo | C31: 4 | D31: 25 | E31: =AVERAGE('TOMA DE DATOS'!$AM$30:$AM$54) -> 11.912 | F31: dominante
A32: 31 | B32: Viejo | C32: 4 | D32: 19 | E32: 10.6 | F32: dominante
A33: 32 | B33: Nuevo | C33: 2 | D33: 17 | E33: =AVERAGE('TOMA DE DATOS'!$AU$30:$AU$46) -> 11.588235 | F33: no dominante
A34: 33 | B34: Nuevo | C34: 3 | D34: 12 | E34: =AVERAGE('TOMA DE DATOS'!$AY$30:$AY$41) -> 12.683333 | F34: no dominante
A35: 34 | B35: Nuevo | C35: 3 | D35: 3 | E35: =AVERAGE('TOMA DE DATOS'!$BC$30:$BC$32) -> 8.5 | F35: no dominante
A36: 35 | B36: Nuevo | C36: 3 | D36: 21 | E36: =AVERAGE('TOMA DE DATOS'!$BG$30:$BG$50) -> 13.342857 | F36: dominante
A37: 36 | B37: Nuevo | C37: 3 | D37: 17 | E37: =AVERAGE('TOMA DE DATOS'!$BK$30:$BK$46) -> 15.879412 | F37: no dominante
A38: 37 | B38: Viejo | C38: 1 | D38: 25 | E38: =AVERAGE('TOMA DE DATOS'!$BO$30:$BO$54) -> 9.764 | F38: no dominante
A39: 38 | B39: Viejo | C39: 1 | D39: 40 | E39: =AVERAGE('TOMA DE DATOS'!$BS$31:$BS$70) -> 10.6405 | F39: dominante
A40: 39 | B40: Viejo | C40: 1 | D40: 27 | E40: =AVERAGE('TOMA DE DATOS'!$BW$31:$BW$57) -> 10.267407 | F40: dominante
A41: 40 | B41: Viejo | C41: 1 | D41: 25 | E41: =AVERAGE('TOMA DE DATOS'!$CA$31:$CA$55) -> 10.9056 | F41: no dominante
A42: 41 | B42: Viejo | C42: 1 | D42: 25 | E42: =AVERAGE('TOMA DE DATOS'!$C$52:$C$76) -> 14.1784 | F42: dominante
A43: 42 | B43: Viejo | C43: 3 | D43: 24 | E43: 11.81 | F43: no dominante
A44: 43 | B44: Viejo | C44: 3 | D44: 24 | E44: =AVERAGE('TOMA DE DATOS'!$K$52:$K$75) -> 11.344167 | F44: dominante
A45: 44 | B45: Nuevo | C45: 3 | D45: 7 | E45: =AVERAGE('TOMA DE DATOS'!$O$71:$O$77) -> 12.938571 | F45: no dominante
A46: 45 | B46: Nuevo | C46: 3 | D46: 22 | E46: =AVERAGE('TOMA DE DATOS'!$S$59:$S$80) -> 36.12619 | F46: dominante
A47: 46 | B47: Nuevo | C47: 3 | D47: 24 | E47: =AVERAGE('TOMA DE DATOS'!$W$59:$W$82) -> 20.673333 | F47: no dominante
A48: 47 | B48: Nuevo | C48: 4 | D48: 29 | E48: =AVERAGE('TOMA DE DATOS'!$AA$73:$AA$101) -> 54.063448 | F48: dominante
A49: 48 | B49: Nuevo | C49: 1 | D49: 14 | E49: =AVERAGE('TOMA DE DATOS'!$AE$65:$AE$78) -> 18.665 | F49: dominante
...
